(.venv) davidmutascio@Davids-MacBook-Pro enigmaTrainer_again % python trainer.py\
Training LSTM model: 100%|\uc0\u9608 \u9608 \u9608 \u9608 \u9608 \u9608 \u9608 \u9608 \u9608 \u9608 \u9608 \u9608 \u9608 \u9608 \u9608 \u9608 \u9608 | 100/100 [50:48<00:00, 30.49s/it, Loss=0.0000]\
/Users/davidmutascio/Desktop/enigmaTrainer_again/.venv/lib/python3.10/site-packages/torch/nn/modules/transformer.py:307: UserWarning: enable_nested_tensor is True, but self.use_nested_tensor is False because encoder_layer.self_attn.batch_first was not True(use batch_first for better inference performance)\
  warnings.warn(f"enable_nested_tensor is True, but self.use_nested_tensor is False because \{why_not_sparsity_fast_path\}")\
Training TRANSFORMER model: 100%|\uc0\u9608 \u9608 \u9608 \u9608 \u9608 \u9608 \u9608 \u9608 \u9608 \u9608 \u9608 \u9608 \u9608 \u9608 \u9608 \u9608 \u9608 \u9608 \u9608 \u9608 \u9608 \u9608 \u9608 \u9608 \u9608 \u9608 \u9608 \u9608 \u9608 \u9608 \u9608 \u9608 \u9608 \u9608 \u9608 \u9608 \u9608 \u9608 \u9608 \u9608 \u9608 \u9608 \u9608 \u9608 \u9608 \u9608 \u9608 \u9608 \u9608 \u9608 \u9608 \u9608 \u9608 \u9608 \u9608 \u9608 \u9608 \u9608 \u9608 \u9608 \u9608 \u9608 \u9608 \u9608 \u9608 \u9608 \u9608 \u9608 \u9608 \u9608 \u9608 \u9608 \u9608 \u9608 \u9608 \u9608 \u9608 \u9608 \u9608 \u9608 \u9608 \u9608 \u9608 \u9608 \u9608 \u9608 \u9608 \u9608 \u9608 | 100/100 [2:59:25<00:00, 107.66s/it, Loss=0.0000]\
multiprocessing.pool.RemoteTraceback:\
"""\
Traceback (most recent call last):\
  File "/Users/davidmutascio/Desktop/enigmaTrainer_again/.venv/lib/python3.10/site-packages/alpaca/common/rest.py", line 196, in _one_request\
    response.raise_for_status()\
  File "/Users/davidmutascio/Desktop/enigmaTrainer_again/.venv/lib/python3.10/site-packages/requests/models.py", line 1024, in raise_for_status\
    raise HTTPError(http_error_msg, response=self)\
requests.exceptions.HTTPError: 403 Client Error: Forbidden for url: https://paper-api.alpaca.markets/v2/orders\
\
During handling of the above exception, another exception occurred:\
\
Traceback (most recent call last):\
  File "/Library/Frameworks/Python.framework/Versions/3.10/lib/python3.10/multiprocessing/pool.py", line 125, in worker\
    result = (True, func(*args, **kwds))\
  File "/Library/Frameworks/Python.framework/Versions/3.10/lib/python3.10/multiprocessing/pool.py", line 48, in mapstar\
    return list(map(*args))\
  File "/Users/davidmutascio/Desktop/enigmaTrainer_again/trainer.py", line 233, in process_stock\
  File "/Users/davidmutascio/Desktop/enigmaTrainer_again/trainer.py", line 195, in trade\
    position = balance // data[i+60, 0]\
  File "/Users/davidmutascio/Desktop/enigmaTrainer_again/.venv/lib/python3.10/site-packages/alpaca/trading/client.py", line 98, in submit_order\
    response = self.post("/orders", data)\
  File "/Users/davidmutascio/Desktop/enigmaTrainer_again/.venv/lib/python3.10/site-packages/alpaca/common/rest.py", line 236, in post\
    return self._request("POST", path, data)\
  File "/Users/davidmutascio/Desktop/enigmaTrainer_again/.venv/lib/python3.10/site-packages/alpaca/common/rest.py", line 129, in _request\
    return self._one_request(method, url, opts, retry)\
  File "/Users/davidmutascio/Desktop/enigmaTrainer_again/.venv/lib/python3.10/site-packages/alpaca/common/rest.py", line 205, in _one_request\
    raise APIError(error, http_error)\
alpaca.common.exceptions.APIError: \{"buying_power":"200000","code":40310000,"cost_basis":"5265141401.8","message":"insufficient buying power"\}\
"""\
\
The above exception was the direct cause of the following exception:\
\
Traceback (most recent call last):\
  File "/Users/davidmutascio/Desktop/enigmaTrainer_again/trainer.py", line 257, in <module>\
    seq_length=seq_length, lstm_params=lstm_params,\
  File "/Library/Frameworks/Python.framework/Versions/3.10/lib/python3.10/multiprocessing/pool.py", line 367, in map\
    return self._map_async(func, iterable, mapstar, chunksize).get()\
  File "/Library/Frameworks/Python.framework/Versions/3.10/lib/python3.10/multiprocessing/pool.py", line 774, in get\
    raise self._value\
alpaca.common.exceptions.APIError: \{"buying_power":"200000","code":40310000,"cost_basis":"5265141401.8","message":"insufficient buying power"\}\
(.venv) davidmutascio@Davids-MacBook-Pro enigmaTrainer_again % /Library/Frameworks/Python.framework/Versions/3.10/lib/python3.10/multiprocessing/resource_tracker.py:224: UserWarning: resource_tracker: There appear to be 1 leaked semaphore objects to clean up at shutdown\
  warnings.warn('resource_tracker: There appear to be %d '\
}
